[2024-07-19T15:12:28.538+0000] {local_task_job_runner.py:120} INFO - ::group::Pre task execution logs
[2024-07-19T15:12:28.558+0000] {taskinstance.py:2076} INFO - Dependencies all met for dep_context=non-requeueable deps ti=<TaskInstance: newdag.captura_conta_dados scheduled__2024-07-19T12:30:00+00:00 [queued]>
[2024-07-19T15:12:28.563+0000] {taskinstance.py:2076} INFO - Dependencies all met for dep_context=requeueable deps ti=<TaskInstance: newdag.captura_conta_dados scheduled__2024-07-19T12:30:00+00:00 [queued]>
[2024-07-19T15:12:28.564+0000] {taskinstance.py:2306} INFO - Starting attempt 13 of 13
[2024-07-19T15:12:28.575+0000] {taskinstance.py:2330} INFO - Executing <Task(PythonOperator): captura_conta_dados> on 2024-07-19 12:30:00+00:00
[2024-07-19T15:12:28.580+0000] {warnings.py:112} WARNING - /home/***/.local/lib/python3.12/site-packages/***/task/task_runner/standard_task_runner.py:62: DeprecationWarning: This process (pid=1895) is multi-threaded, use of fork() may lead to deadlocks in the child.
  pid = os.fork()

[2024-07-19T15:12:28.581+0000] {standard_task_runner.py:90} INFO - Running: ['***', 'tasks', 'run', 'newdag', 'captura_conta_dados', 'scheduled__2024-07-19T12:30:00+00:00', '--job-id', '41', '--raw', '--subdir', 'DAGS_FOLDER/firstdag.py', '--cfg-path', '/tmp/tmptgdujdvq']
[2024-07-19T15:12:28.581+0000] {standard_task_runner.py:64} INFO - Started process 1904 to run task
[2024-07-19T15:12:28.581+0000] {standard_task_runner.py:91} INFO - Job 41: Subtask captura_conta_dados
[2024-07-19T15:12:28.613+0000] {task_command.py:426} INFO - Running <TaskInstance: newdag.captura_conta_dados scheduled__2024-07-19T12:30:00+00:00 [running]> on host 11dd3049148c
[2024-07-19T15:12:28.676+0000] {taskinstance.py:2648} INFO - Exporting env vars: AIRFLOW_CTX_DAG_OWNER='***' AIRFLOW_CTX_DAG_ID='newdag' AIRFLOW_CTX_TASK_ID='captura_conta_dados' AIRFLOW_CTX_EXECUTION_DATE='2024-07-19T12:30:00+00:00' AIRFLOW_CTX_TRY_NUMBER='13' AIRFLOW_CTX_DAG_RUN_ID='scheduled__2024-07-19T12:30:00+00:00'
[2024-07-19T15:12:28.677+0000] {taskinstance.py:430} INFO - ::endgroup::
[2024-07-19T15:12:29.047+0000] {taskinstance.py:441} INFO - ::group::Post task execution logs
[2024-07-19T15:12:29.047+0000] {taskinstance.py:2905} ERROR - Task failed with exception
Traceback (most recent call last):
  File "/home/airflow/.local/lib/python3.12/site-packages/requests/models.py", line 974, in json
    return complexjson.loads(self.text, **kwargs)
           ^^^^^^^^^^^^^^^^^^^^^^^^^^^^^^^^^^^^^^
  File "/usr/local/lib/python3.12/json/__init__.py", line 346, in loads
    return _default_decoder.decode(s)
           ^^^^^^^^^^^^^^^^^^^^^^^^^^
  File "/usr/local/lib/python3.12/json/decoder.py", line 337, in decode
    obj, end = self.raw_decode(s, idx=_w(s, 0).end())
               ^^^^^^^^^^^^^^^^^^^^^^^^^^^^^^^^^^^^^^
  File "/usr/local/lib/python3.12/json/decoder.py", line 355, in raw_decode
    raise JSONDecodeError("Expecting value", s, err.value) from None
json.decoder.JSONDecodeError: Expecting value: line 1 column 1 (char 0)

During handling of the above exception, another exception occurred:

Traceback (most recent call last):
  File "/home/airflow/.local/lib/python3.12/site-packages/airflow/models/taskinstance.py", line 465, in _execute_task
    result = _execute_callable(context=context, **execute_callable_kwargs)
             ^^^^^^^^^^^^^^^^^^^^^^^^^^^^^^^^^^^^^^^^^^^^^^^^^^^^^^^^^^^^^
  File "/home/airflow/.local/lib/python3.12/site-packages/airflow/models/taskinstance.py", line 432, in _execute_callable
    return execute_callable(context=context, **execute_callable_kwargs)
           ^^^^^^^^^^^^^^^^^^^^^^^^^^^^^^^^^^^^^^^^^^^^^^^^^^^^^^^^^^^^
  File "/home/airflow/.local/lib/python3.12/site-packages/airflow/models/baseoperator.py", line 401, in wrapper
    return func(self, *args, **kwargs)
           ^^^^^^^^^^^^^^^^^^^^^^^^^^^
  File "/home/airflow/.local/lib/python3.12/site-packages/airflow/operators/python.py", line 235, in execute
    return_value = self.execute_callable()
                   ^^^^^^^^^^^^^^^^^^^^^^^
  File "/home/airflow/.local/lib/python3.12/site-packages/airflow/operators/python.py", line 252, in execute_callable
    return self.python_callable(*self.op_args, **self.op_kwargs)
           ^^^^^^^^^^^^^^^^^^^^^^^^^^^^^^^^^^^^^^^^^^^^^^^^^^^^^
  File "/opt/airflow/dags/firstdag.py", line 17, in captura_conta_dados
    df = pd.DataFrame(response.json())
                      ^^^^^^^^^^^^^^^
  File "/home/airflow/.local/lib/python3.12/site-packages/requests/models.py", line 978, in json
    raise RequestsJSONDecodeError(e.msg, e.doc, e.pos)
requests.exceptions.JSONDecodeError: Expecting value: line 1 column 1 (char 0)
[2024-07-19T15:12:29.057+0000] {taskinstance.py:1206} INFO - Marking task as FAILED. dag_id=newdag, task_id=captura_conta_dados, run_id=scheduled__2024-07-19T12:30:00+00:00, execution_date=20240719T123000, start_date=20240719T151228, end_date=20240719T151229
[2024-07-19T15:12:29.066+0000] {standard_task_runner.py:110} ERROR - Failed to execute job 41 for task captura_conta_dados (Expecting value: line 1 column 1 (char 0); 1904)
[2024-07-19T15:12:29.076+0000] {local_task_job_runner.py:243} INFO - Task exited with return code 1
[2024-07-19T15:12:29.093+0000] {taskinstance.py:3503} INFO - 0 downstream tasks scheduled from follow-on schedule check
[2024-07-19T15:12:29.096+0000] {local_task_job_runner.py:222} INFO - ::endgroup::
